Workbook

Sheet Leia-me
B2: Grupo Meridiano Varejo Ltda
B3: Dataset financeiro sintetico e integrado | Base de conhecimento para o Agente Expert em Financas
B5: 1. Objetivo
B6: Este arquivo e um conjunto de dados financeiros completo e internamente consistente, criado para alimentar e testar o Agente Expert em Financas da Draiven. Ele simula as tres demonstracoes contabeis de um grupo varejista consolidado ao longo de 36 meses (jan/2025 a dez/2027), com todos os indicadores que um especialista senior de FP&A analisaria: margens, liquidez, ciclo de conversao de caixa, endividamento, ROIC, cenarios e sensibilidade.
B8: 2. Entidade simulada
B9: Grupo Meridiano Varejo Ltda (entidade ficticia) e um grupo consolidado com cinco unidades de negocio: Materiais de Construcao, Utilidades Domesticas, Papelaria e Impressao, Servicos Automotivos e Vestuario. Cada unidade tem perfil proprio de margem, sazonalidade, prazos e crescimento.
B11: 3. Procedencia dos dados
B12: Receita 2025 e 2026 | C12: Real. Derivada de notas fiscais agregadas por mes e por unidade (linha de topo verdadeira). Sao as celulas de receita e impostos em azul na aba DRE_por_UN.
B13: Projecao 2027 | C13: Modelada. Cada mes de 2027 parte do mesmo mes de 2026 e aplica o crescimento por unidade definido em Premissas.
B14: Custos, balanco e fluxo | C14: Sinteticos. CMV, folha, ocupacao, capital de giro, imobilizado, divida, impostos e dividendos sao modelados a partir dos drivers em Premissas. Nenhum custo real foi usado.
B16: 4. Estrutura das abas
B17: Premissas | C17: Painel de controle. Todos os inputs ajustaveis (celulas azuis): parametros globais, saldos de abertura, drivers por unidade, aging e multiplicadores de cenario.
B18: DRE_Consolidado | C18: Demonstracao de resultado mensal consolidada, com totais anuais 2025 a 2027.
B19: Balanco_Consolidado | C19: Balanco patrimonial mensal. A ultima linha (Checagem) confirma que Ativo = Passivo + PL em todos os meses (deve ser zero).
B20: DFC_Consolidado | C20: Fluxo de caixa pelo metodo indireto, conciliado linha a linha com o balanco.
B21: KPIs_Mensais | C21: Vinte indicadores por mes: margens, crescimento, DSO/DIO/DPO, ciclo de caixa, liquidez, divida liquida/EBITDA, cobertura de juros, ROIC e geracao de caixa.
B22: Cenarios | C22: Resultado de 2027 sob tres cenarios (Conservador, Base, Otimista) a partir dos multiplicadores em Premissas.
B23: Sensibilidade | C23: Dois grids 2D: EBITDA e Lucro Liquido de 2027 variando crescimento, margem bruta e custos.
B24: DRE_por_UN | C24: Espinha dorsal (formato tidy). Resultado ate EBITDA por unidade e por mes. Fonte de todas as agregacoes.
B25: Headcount_Folha | C25: Quadro de pessoal e folha (com encargos) por unidade e mes.
B26: Estoque | C26: Estoque, giro e DIO por unidade e mes.
B27: Contas_Receber | C27: Contas a receber, DSO e aging por unidade e mes.
B28: Contas_Pagar | C28: Contas a pagar, DPO e aging por unidade e mes.
... B30: CMV_Custos_Produto | C30: Referencia de custo e margem por produto, com precos medios reais das notas fiscais.
B32: 5. Dinamicas embutidas (gabarito para validar o agente)
B33: O dataset contem padroes intencionais e conhecidos. Um agente de financas competente deve identifica-los. Use esta lista como gabarito ao avaliar as analises geradas:
B34: Rentabilidade declinante | C34: Receita cresce todo ano, mas EBITDA e margem liquida caem (margem EBITDA ~8,6% em 2025 para ~5,6% em 2027). O agente deve notar que crescimento nao virou lucro.
B35: Compressao de margem | C35: Utilidades Domesticas, a maior unidade em volume, tem margem bruta caindo de 38% (2025) para 32% (2027). E o principal motor da queda de rentabilidade.
B36: Deterioracao de capital de giro | C36: DSO consolidado sobe de ~21 para ~26 dias e o ciclo de conversao de caixa se alonga, pressionando o caixa operacional.
B37: Sazonalidade | C37: Vestuario concentra vendas em novembro e dezembro. Meses de janeiro sao fracos e chegam a gerar prejuizo pontual.
B38: Ciclo de capex | C38: Ha uma reforma de lojas concentrada entre junho e agosto de 2025, visivel no fluxo de investimento.
B39: Posicao de caixa liquido | C39: O grupo mantem mais caixa do que divida (divida liquida negativa), entao multiplos como Divida Liquida/EBITDA aparecem negativos por construcao.
B41: 6. Convencoes
B42: Azul | C42: Input ajustavel pelo usuario.
B43: Preto | C43: Formula calculada dentro da propria aba.
B44: Verde | C44: Formula que busca dados de outra aba.
B45: Moeda em Reais (R$), sem casas decimais. Percentuais e dias com uma casa. Multiplos com "x".
B47: 7. Como usar
B48: Altere qualquer celula azul na aba Premissas (ou no Cronograma da linha de capital de giro) e recalcule a planilha. Todo o modelo, incluindo balanco, fluxo de caixa e KPIs, se atualiza. Os cenarios e a sensibilidade sao sobrepostos analiticos sobre 2027 e nao alteram o modelo mensal principal, que representa o caso Base.
B50: 8. Integridade do modelo
...

Sheet Premissas
A1: PREMISSAS E DRIVERS DO MODELO
A2: Grupo Meridiano Varejo Ltda (entidade sintetica) | Todas as celulas azuis sao inputs ajustaveis
A4: PARAMETROS GLOBAIS
A5: IR/CSLL - aliquota efetiva sobre LAIR | B5: 0.34
A6: Taxa de juros da divida (% a.m.) | B6: 0.016
A7: Taxa de rendimento do caixa (% a.m.) | B7: 0.009
A8: Overhead corporativo / G&A (R$ / mes, base 2025) | B8: 8000
A9: Reajuste anual do overhead corporativo | B9: 0.06
A10: Capex de manutencao (% da receita liquida) | B10: 0.015
A11: Vida util media do imobilizado (meses) | B11: 120
A12: Payout de dividendos (% do lucro do ano anterior) | B12: 0.3
A13: Outros ativos circulantes (% receita liquida do mes) | B13: 0.08
A14: Outros passivos circulantes (% receita liquida do mes) | B14: 0.1
A15: Provisoes trabalhistas (% da folha do mes) | B15: 0.4
A17: SALDOS DE ABERTURA (Dez/2024)
A18: Contas a receber - abertura | B18: 130000
A19: Estoques - abertura | B19: 180000
A20: Outros ativos circulantes - abertura | B20: 16000
A21: Imobilizado bruto - abertura | B21: 500000
A22: Depreciacao acumulada - abertura | B22: 120000
A23: Intangivel liquido - abertura | B23: 40000
A24: Fornecedores - abertura | B24: 150000
A25: Obrigacoes fiscais - abertura | B25: 95000
A26: Obrigacoes trabalhistas - abertura | B26: 15000
A27: Outros passivos circulantes - abertura | B27: 20000
A28: Emprestimo termo - saldo abertura | B28: 250000
A29: Linha capital de giro - saldo abertura | B29: 80000
... A34: Amortizacao mensal do emprestimo termo (R$) | B34: 5000
A35: Caixa e equivalentes - abertura (PLUG p/ balancear) | B35: =(Premissas!$B$24+Premissas!$B$30+Premissas!$B$25+Premissas!$B$26+Premissas!$B$27+Premissas!$B$31+Premissas!$B$32+Premissas!$B$33)-(Premissas!$B$18+Premissas!$B$19+Premissas!$B$20+(Premissas!$B$21-Premissas!$B$22)+Premissas!$B$23) -> 464000
A37: Capex de expansao (reforma de lojas) - total R$ 90k em Jun-Ago/2025
A38: Capex expansao por mes (Jun,Jul,Ago 2025) | B38: 30000
A40: DISTRIBUICAO DE AGING (Contas a Receber e Pagar)
A41: Faixa | B41: A vencer | C41: 1-30 dias | D41: 31-60 dias | E41: 61-90 dias | F41: > 90 dias
A42: % da carteira | B42: 0.7 | C42: 0.15 | D42: 0.08 | E42: 0.04 | F42: 0.03
A44: CENARIOS (aplicados na projecao 2027 - aba Cenarios)
A45: Cenario | B45: Mult. crescimento | C45: Delta margem (p.p.) | D45: Mult. opex var.
A46: Conservador | B46: 0.5 | C46: -0.02 | D46: 1.04
A47: Base | B47: 1 | C47: 0 | D47: 1
A48: Otimista | B48: 1.5 | C48: 0.015 | D48: 0.97
A50: DRIVERS POR UNIDADE DE NEGOCIO
...

Sheet DRE_Consolidado
A1: DRE CONSOLIDADO - Grupo Meridiano Varejo (mensal, R$)
A2: Linha | C2: 2025-01 | D2: 2025-02 | E2: 2025-03 | F2: 2025-04 | G2: 2025-05 | H2: 2025-06 | I2: 2025-07 | J2: 2025-08 | K2: 2025-09 | L2: 2025-10 | M2: 2025-11 | N2: 2025-12 | O2: 2026-01 | P2: 2026-02 | Q2: 2026-03 | R2: 2026-04 | S2: 2026-05 | T2: 2026-06 | U2: 2026-07 | V2: 2026-08 | W2: 2026-09 | X2: 2026-10 | Y2: 2026-11 | Z2: 2026-12 | AA2: 2027-01 | AB2: 2027-02 | AC2: 2027-03 | AD2: 2027-04 | AE2: 2027-05 | AF2: 2027-06 | AG2: 2027-07 | AH2: 2027-08 | AI2: 2027-09 | AJ2: 2027-10 | AK2: 2027-11 | AL2: 2027-12 | AN2: 2025 | AO2: 2026 | AP2: 2027
C3: 2025 | D3: 2025 | E3: 2025 | F3: 2025 | G3: 2025 | H3: 2025 | I3: 2025 | J3: 2025 | K3: 2025 | L3: 2025 | M3: 2025 | N3: 2025 | O3: 2026 | P3: 2026 | Q3: 2026 | R3: 2026 | S3: 2026 | T3: 2026 | U3: 2026 | V3: 2026 | W3: 2026 | X3: 2026 | Y3: 2026 | Z3: 2026 | AA3: 2027 | AB3: 2027 | AC3: 2027 | AD3: 2027 | AE3: 2027 | AF3: 2027 | AG3: 2027 | AH3: 2027 | AI3: 2027 | AJ3: 2027 | AK3: 2027 | AL3: 2027 | AN3: Total | AO3: Total | AP3: Total
A4: Receita Bruta | C4: =SUMIFS(DRE_por_UN!$F:$F,DRE_por_UN!$C:$C,C$2) -> 261382.1 | D4: =SUMIFS(DRE_por_UN!$F:$F,DRE_por_UN!$C:$C,D$2) -> 250904.51 | E4: =SUMIFS(DRE_por_UN!$F:$F,DRE_por_UN!$C:$C,E$2) -> 277234.2 | F4: =SUMIFS(DRE_por_UN!$F:$F,DRE_por_UN!$C:$C,F$2) -> 280943.75 | G4: =SUMIFS(DRE_por_UN!$F:$F,DRE_por_UN!$C:$C,G$2) -> 285858.47 | H4: =SUMIFS(DRE_por_UN!$F:$F,DRE_por_UN!$C:$C,H$2) -> 311626.4 | I4: =SUMIFS(DRE_por_UN!$F:$F,DRE_por_UN!$C:$C,I$2) -> 314185.58 | J4: =SUMIFS(DRE_por_UN!$F:$F,DRE_por_UN!$C:$C,J$2) -> 276259.76 | ... AL4: =SUMIFS(DRE_por_UN!$F:$F,DRE_por_UN!$C:$C,AL$2) -> 426285.15 | AN4: =SUMIF($C$3:$AL$3,2025,$C4:$AL4) -> 3574762.7 | AO4: =SUMIF($C$3:$AL$3,2026,$C4:$AL4) -> 3763378.7 | AP4: =SUMIF($C$3:$AL$3,2027,$C4:$AL4) -> 4032546.8
A5: (-) Impostos sobre Vendas | C5: =-SUMIFS(DRE_por_UN!$G:$G,DRE_por_UN!$C:$C,C$2) -> -86466.46 | D5: =-SUMIFS(DRE_por_UN!$G:$G,DRE_por_UN!$C:$C,D$2) -> -80445.58 | E5: =-SUMIFS(DRE_por_UN!$G:$G,DRE_por_UN!$C:$C,E$2) -> -90609.13 | F5: =-SUMIFS(DRE_por_UN!$G:$G,DRE_por_UN!$C:$C,F$2) -> -89539.31 | G5: =-SUMIFS(DRE_por_UN!$G:$G,DRE_por_UN!$C:$C,G$2) -> -92063.98 | H5: =-SUMIFS(DRE_por_UN!$G:$G,DRE_por_UN!$C:$C,H$2) -> -101067.89 | I5: =-SUMIFS(DRE_por_UN!$G:$G,DRE_por_UN!$C:$C,I$2) -> -100997.11 | J5: =-SUMIFS(DRE_por_UN!$G:$G,DRE_por_UN!$C:$C,J$2) -> -88389.26 | ... AL5: =-SUMIFS(DRE_por_UN!$G:$G,DRE_por_UN!$C:$C,AL$2) -> -138084.05 | AN5: =SUMIF($C$3:$AL$3,2025,$C5:$AL5) -> -1156384.7 | AO5: =SUMIF($C$3:$AL$3,2026,$C5:$AL5) -> -1206831.2 | AP5: =SUMIF($C$3:$AL$3,2027,$C5:$AL5) -> -1311306.5
A6: Receita Liquida | C6: =C4+C5 -> 174915.64 | D6: =D4+D5 -> 170458.93 | E6: =E4+E5 -> 186625.07 | F6: =F4+F5 -> 191404.44 | G6: =G4+G5 -> 193794.49 | H6: =H4+H5 -> 210558.51 | I6: =I4+I5 -> 213188.47 | J6: =J4+J5 -> 187870.5 | ... AL6: =AL4+AL5 -> 288201.1 | AN6: =SUMIF($C$3:$AL$3,2025,$C6:$AL6) -> 2418378 | AO6: =SUMIF($C$3:$AL$3,2026,$C6:$AL6) -> 2556547.5 | AP6: =SUMIF($C$3:$AL$3,2027,$C6:$AL6) -> 2721240.3
A7: (-) CMV | C7: =-SUMIFS(DRE_por_UN!$J:$J,DRE_por_UN!$C:$C,C$2) -> -97086.387 | D7: =-SUMIFS(DRE_por_UN!$J:$J,DRE_por_UN!$C:$C,D$2) -> -95557.916 | E7: =-SUMIFS(DRE_por_UN!$J:$J,DRE_por_UN!$C:$C,E$2) -> -103385.47 | F7: =-SUMIFS(DRE_por_UN!$J:$J,DRE_por_UN!$C:$C,F$2) -> -105861.73 | G7: =-SUMIFS(DRE_por_UN!$J:$J,DRE_por_UN!$C:$C,G$2) -> -108114.01 | H7: =-SUMIFS(DRE_por_UN!$J:$J,DRE_por_UN!$C:$C,H$2) -> -118057.96 | I7: =-SUMIFS(DRE_por_UN!$J:$J,DRE_por_UN!$C:$C,I$2) -> -119272.14 | J7: =-SUMIFS(DRE_por_UN!$J:$J,DRE_por_UN!$C:$C,J$2) -> -104540.97 | ... AL7: =-SUMIFS(DRE_por_UN!$J:$J,DRE_por_UN!$C:$C,AL$2) -> -163050.32 | AN7: =SUMIF($C$3:$AL$3,2025,$C7:$AL7) -> -1346276.9 | AO7: =SUMIF($C$3:$AL$3,2026,$C7:$AL7) -> -1436488 | AP7: =SUMIF($C$3:$AL$3,2027,$C7:$AL7) -> -1533792.9
A8: Lucro Bruto | C8: =C6+C7 -> 77829.253 | D8: =D6+D7 -> 74901.014 | E8: =E6+E7 -> 83239.596 | F8: =F6+F7 -> 85542.711 | G8: =G6+G7 -> 85680.48 | H8: =H6+H7 -> 92500.555 | I8: =I6+I7 -> 93916.328 | J8: =J6+J7 -> 83329.526 | ... AL8: =AL6+AL7 -> 125150.78 | AN8: =SUMIF($C$3:$AL$3,2025,$C8:$AL8) -> 1072101.1 | AO8: =SUMIF($C$3:$AL$3,2026,$C8:$AL8) -> 1120059.5 | AP8: =SUMIF($C$3:$AL$3,2027,$C8:$AL8) -> 1187447.4
A9: Margem Bruta % | C9: =IF(C6=0,0,C8/C6) -> 0.44495308 | D9: =IF(D6=0,0,D8/D6) -> 0.43940798 | E9: =IF(E6=0,0,E8/E6) -> 0.4460258 | F9: =IF(F6=0,0,F8/F6) -> 0.44692125 | G9: =IF(G6=0,0,G8/G6) -> 0.44212031 | H9: =IF(H6=0,0,H8/H6) -> 0.43931046 | I9: =IF(I6=0,0,I8/I6) -> 0.44053193 | J9: =IF(J6=0,0,J8/J6) -> 0.44354769 | ... AL9: =IF(AL6=0,0,AL8/AL6) -> 0.43424809 | AN9: =IF(AN6=0,0,AN8/AN6) -> 0.44331412 | AO9: =IF(AO6=0,0,AO8/AO6) -> 0.4381141 | AP9: =IF(AP6=0,0,AP8/AP6) -> 0.43636255
A10: (-) Folha Direta | C10: =-SUMIFS(DRE_por_UN!$L:$L,DRE_por_UN!$C:$C,C$2) -> -38136 | D10: =-SUMIFS(DRE_por_UN!$L:$L,DRE_por_UN!$C:$C,D$2) -> -38136 | E10: =-SUMIFS(DRE_por_UN!$L:$L,DRE_por_UN!$C:$C,E$2) -> -38136 | F10: =-SUMIFS(DRE_por_UN!$L:$L,DRE_por_UN!$C:$C,F$2) -> -38136 | G10: =-SUMIFS(DRE_por_UN!$L:$L,DRE_por_UN!$C:$C,G$2) -> -38136 | H10: =-SUMIFS(DRE_por_UN!$L:$L,DRE_por_UN!$C:$C,H$2) -> -38136 | I10: =-SUMIFS(DRE_por_UN!$L:$L,DRE_por_UN!$C:$C,I$2) -> -38136 | J10: =-SUMIFS(DRE_por_UN!$L:$L,DRE_por_UN!$C:$C,J$2) -> -38136 | ... AL10: =-SUMIFS(DRE_por_UN!$L:$L,DRE_por_UN!$C:$C,AL$2) -> -48720 | AN10: =SUMIF($C$3:$AL$3,2025,$C10:$AL10) -> -457632 | AO10: =SUMIF($C$3:$AL$3,2026,$C10:$AL10) -> -510048 | AP10: =SUMIF($C$3:$AL$3,2027,$C10:$AL10) -> -584640
A11: (-) Aluguel/Ocupacao | C11: =-SUMIFS(DRE_por_UN!$M:$M,DRE_por_UN!$C:$C,C$2) -> -11500 | D11: =-SUMIFS(DRE_por_UN!$M:$M,DRE_por_UN!$C:$C,D$2) -> -11500 | E11: =-SUMIFS(DRE_por_UN!$M:$M,DRE_por_UN!$C:$C,E$2) -> -11500 | F11: =-SUMIFS(DRE_por_UN!$M:$M,DRE_por_UN!$C:$C,F$2) -> -11500 | G11: =-SUMIFS(DRE_por_UN!$M:$M,DRE_por_UN!$C:$C,G$2) -> -11500 | H11: =-SUMIFS(DRE_por_UN!$M:$M,DRE_por_UN!$C:$C,H$2) -> -11500 | I11: =-SUMIFS(DRE_por_UN!$M:$M,DRE_por_UN!$C:$C,I$2) -> -11500 | J11: =-SUMIFS(DRE_por_UN!$M:$M,DRE_por_UN!$C:$C,J$2) -> -11500 | ... AL11: =-SUMIFS(DRE_por_UN!$M:$M,DRE_por_UN!$C:$C,AL$2) -> -12558.288 | AN11: =SUMIF($C$3:$AL$3,2025,$C11:$AL11) -> -138000 | AO11: =SUMIF($C$3:$AL$3,2026,$C11:$AL11) -> -144210 | AP11: =SUMIF($C$3:$AL$3,2027,$C11:$AL11) -> -150699.45
A12: (-) Marketing | C12: =-SUMIFS(DRE_por_UN!$N:$N,DRE_por_UN!$C:$C,C$2) -> -4180.487 | D12: =-SUMIFS(DRE_por_UN!$N:$N,DRE_por_UN!$C:$C,D$2) -> -3964.1712 | E12: =-SUMIFS(DRE_por_UN!$N:$N,DRE_por_UN!$C:$C,E$2) -> -4436.1659 | F12: =-SUMIFS(DRE_por_UN!$N:$N,DRE_por_UN!$C:$C,F$2) -> -4528.0571 | G12: =-SUMIFS(DRE_por_UN!$N:$N,DRE_por_UN!$C:$C,G$2) -> -4557.3676 | H12: =-SUMIFS(DRE_por_UN!$N:$N,DRE_por_UN!$C:$C,H$2) -> -4935.0675 | I12: =-SUMIFS(DRE_por_UN!$N:$N,DRE_por_UN!$C:$C,I$2) -> -4976.5728 | J12: =-SUMIFS(DRE_por_UN!$N:$N,DRE_por_UN!$C:$C,J$2) -> -4457.7932 | ... AL12: =-SUMIFS(DRE_por_UN!$N:$N,DRE_por_UN!$C:$C,AL$2) -> -6788.7931 | AN12: =SUMIF($C$3:$AL$3,2025,$C12:$AL12) -> -57110.663 | AO12: =SUMIF($C$3:$AL$3,2026,$C12:$AL12) -> -60469.046 | AP12: =SUMIF($C$3:$AL$3,2027,$C12:$AL12) -> -64417.348
A13: (-) Frete/Logistica | C13: =-SUMIFS(DRE_por_UN!$O:$O,DRE_por_UN!$C:$C,C$2) -> -4649.7356 | D13: =-SUMIFS(DRE_por_UN!$O:$O,DRE_por_UN!$C:$C,D$2) -> -4699.1016 | E13: =-SUMIFS(DRE_por_UN!$O:$O,DRE_por_UN!$C:$C,E$2) -> -5055.2644 | F13: =-SUMIFS(DRE_por_UN!$O:$O,DRE_por_UN!$C:$C,F$2) -> -5107.2756 | G13: =-SUMIFS(DRE_por_UN!$O:$O,DRE_por_UN!$C:$C,G$2) -> -5316.8364 | H13: =-SUMIFS(DRE_por_UN!$O:$O,DRE_por_UN!$C:$C,H$2) -> -5917.3043 | I13: =-SUMIFS(DRE_por_UN!$O:$O,DRE_por_UN!$C:$C,I$2) -> -5885.7169 | J13: =-SUMIFS(DRE_por_UN!$O:$O,DRE_por_UN!$C:$C,J$2) -> -5217.7056 | ... AL13: =-SUMIFS(DRE_por_UN!$O:$O,DRE_por_UN!$C:$C,AL$2) -> -7881.2362 | AN13: =SUMIF($C$3:$AL$3,2025,$C13:$AL13) -> -66105.464 | AO13: =SUMIF($C$3:$AL$3,2026,$C13:$AL13) -> -69266.62 | AP13: =SUMIF($C$3:$AL$3,2027,$C13:$AL13) -> -73451.744
A14: (-) Outras Desp. Diretas | C14: =-SUMIFS(DRE_por_UN!$P:$P,DRE_por_UN!$C:$C,C$2) -> -3582.3205 | D14: =-SUMIFS(DRE_por_UN!$P:$P,DRE_por_UN!$C:$C,D$2) -> -3426.0813 | E14: =-SUMIFS(DRE_por_UN!$P:$P,DRE_por_UN!$C:$C,E$2) -> -3759.3547 | F14: =-SUMIFS(DRE_por_UN!$P:$P,DRE_por_UN!$C:$C,F$2) -> -3854.2389 | G14: =-SUMIFS(DRE_por_UN!$P:$P,DRE_por_UN!$C:$C,G$2) -> -3901.8419 | H14: =-SUMIFS(DRE_por_UN!$P:$P,DRE_por_UN!$C:$C,H$2) -> -4232.4221 | I14: =-SUMIFS(DRE_por_UN!$P:$P,DRE_por_UN!$C:$C,I$2) -> -4281.3389 | J14: =-SUMIFS(DRE_por_UN!$P:$P,DRE_por_UN!$C:$C,J$2) -> -3775.8989 | ... AL14: =-SUMIFS(DRE_por_UN!$P:$P,DRE_por_UN!$C:$C,AL$2) -> -5799.3279 | AN14: =SUMIF($C$3:$AL$3,2025,$C14:$AL14) -> -48756.916 | AO14: =SUMIF($C$3:$AL$3,2026,$C14:$AL14) -> -51756.505 | AP14: =SUMIF($C$3:$AL$3,2027,$C14:$AL14) -> -55081.725
A15: EBITDA das Unidades | C15: =C8+C10+C11+C12+C13+C14 -> 15780.71 | D15: =D8+D10+D11+D12+D13+D14 -> 13175.66 | E15: =E8+E10+E11+E12+E13+E14 -> 20352.811 | F15: =F8+F10+F11+F12+F13+F14 -> 22417.139 | G15: =G8+G10+G11+G12+G13+G14 -> 22268.434 | H15: =H8+H10+H11+H12+H13+H14 -> 27779.761 | I15: =I8+I10+I11+I12+I13+I14 -> 29136.7 | J15: =J8+J10+J11+J12+J13+J14 -> 20242.128 | ... AL15: =AL8+AL10+AL11+AL12+AL13+AL14 -> 43403.133 | AN15: =SUMIF($C$3:$AL$3,2025,$C15:$AL15) -> 304496.07 | AO15: =SUMIF($C$3:$AL$3,2026,$C15:$AL15) -> 284309.33 | AP15: =SUMIF($C$3:$AL$3,2027,$C15:$AL15) -> 259157.09
A16: (-) Overhead Corporativo (G&A) | C16: =-Premissas!$B$8*(1+Premissas!$B$9)^(C$3-2025) -> -8000 | D16: =-Premissas!$B$8*(1+Premissas!$B$9)^(D$3-2025) -> -8000 | E16: =-Premissas!$B$8*(1+Premissas!$B$9)^(E$3-2025) -> -8000 | F16: =-Premissas!$B$8*(1+Premissas!$B$9)^(F$3-2025) -> -8000 | G16: =-Premissas!$B$8*(1+Premissas!$B$9)^(G$3-2025) -> -8000 | H16: =-Premissas!$B$8*(1+Premissas!$B$9)^(H$3-2025) -> -8000 | I16: =-Premissas!$B$8*(1+Premissas!$B$9)^(I$3-2025) -> -8000 | J16: =-Premissas!$B$8*(1+Premissas!$B$9)^(J$3-2025) -> -8000 | ... AL16: =-Premissas!$B$8*(1+Premissas!$B$9)^(AL$3-2025) -> -8988.8 | AN16: =SUMIF($C$3:$AL$3,2025,$C16:$AL16) -> -96000 | AO16: =SUMIF($C$3:$AL$3,2026,$C16:$AL16) -> -101760 | AP16: =SUMIF($C$3:$AL$3,2027,$C16:$AL16) -> -107865.6
A17: EBITDA Consolidado | C17: =C15+C16 -> 7780.7099 | D17: =D15+D16 -> 5175.6597 | E17: =E15+E16 -> 12352.811 | F17: =F15+F16 -> 14417.139 | G17: =G15+G16 -> 14268.434 | H17: =H15+H16 -> 19779.761 | I17: =I15+I16 -> 21136.7 | J17: =J15+J16 -> 12242.128 | ... AL17: =AL15+AL16 -> 34414.333 | AN17: =SUMIF($C$3:$AL$3,2025,$C17:$AL17) -> 208496.07 | AO17: =SUMIF($C$3:$AL$3,2026,$C17:$AL17) -> 182549.33 | AP17: =SUMIF($C$3:$AL$3,2027,$C17:$AL17) -> 151291.49
A18: Margem EBITDA % | C18: =IF(C6=0,0,C17/C6) -> 0.044482643 | D18: =IF(D6=0,0,D17/D6) -> 0.030363089 | E18: =IF(E6=0,0,E17/E6) -> 0.066190525 | F18: =IF(F6=0,0,F17/F6) -> 0.075322908 | G18: =IF(G6=0,0,G17/G6) -> 0.073626625 | H18: =IF(H6=0,0,H17/H6) -> 0.0939395 | I18: =IF(I6=0,0,I17/I6) -> 0.099145604 | J18: =IF(J6=0,0,J17/J6) -> 0.065162589 | ... AL18: =IF(AL6=0,0,AL17/AL6) -> 0.11941083 | AN18: =IF(AN6=0,0,AN17/AN6) -> 0.086213184 | AO18: =IF(AO6=0,0,AO17/AO6) -> 0.071404632 | AP18: =IF(AP6=0,0,AP17/AP6) -> 0.055596518
A19: (-) Depreciacao e Amortizacao | C19: =-(Cronogramas!C7+Cronogramas!C11) -> -4855.1978 | D19: =-(Cronogramas!D7+Cronogramas!D11) -> -4876.5052 | E19: =-(Cronogramas!E7+Cronogramas!E11) -> -4899.8333 | F19: =-(Cronogramas!F7+Cronogramas!F11) -> -4923.7588 | G19: =-(Cronogramas!G7+Cronogramas!G11) -> -4947.9832 | H19: =-(Cronogramas!H7+Cronogramas!H11) -> -5224.303 | I19: =-(Cronogramas!I7+Cronogramas!I11) -> -5500.9515 | J19: =-(Cronogramas!J7+Cronogramas!J11) -> -5774.4353 | ... AL19: =-(Cronogramas!AL7+Cronogramas!AL11) -> -6545.3541 | AN19: =SUMIF($C$3:$AL$3,2025,$C19:$AL19) -> -64364.765 | AO19: =SUMIF($C$3:$AL$3,2026,$C19:$AL19) -> -72573.103 | AP19: =SUMIF($C$3:$AL$3,2027,$C19:$AL19) -> -76537.059
A20: EBIT | C20: =C17+C19 -> 2925.5121 | D20: =D17+D19 -> 299.15455 | E20: =E17+E19 -> 7452.978 | F20: =F17+F19 -> 9493.3803 | G20: =G17+G19 -> 9320.451 | H20: =H17+H19 -> 14555.458 | I20: =I17+I19 -> 15635.748 | J20: =J17+J19 -> 6467.6928 | ... AL20: =AL17+AL19 -> 27868.979 | AN20: =SUMIF($C$3:$AL$3,2025,$C20:$AL20) -> 144131.3 | AO20: =SUMIF($C$3:$AL$3,2026,$C20:$AL20) -> 109976.23 | AP20: =SUMIF($C$3:$AL$3,2027,$C20:$AL20) -> 74754.426
A21: (+/-) Resultado Financeiro | C21: =Cronogramas!C24 -> -1104 | D21: =Cronogramas!D24 -> -1164.4387 | E21: =Cronogramas!E24 -> -1032.9368 | F21: =Cronogramas!F24 -> -999.25666 | G21: =Cronogramas!G24 -> -876.23057 | H21: =Cronogramas!H24 -> -813.8763 | I21: =Cronogramas!I24 -> -922.98088 | J21: =Cronogramas!J24 -> -1068.2297 | ... AL21: =Cronogramas!AL24 -> 210.1587 | AN21: =SUMIF($C$3:$AL$3,2025,$C21:$AL21) -> -12328.415 | AO21: =SUMIF($C$3:$AL$3,2026,$C21:$AL21) -> -12554.887 | AP21: =SUMIF($C$3:$AL$3,2027,$C21:$AL21) -> -4429.021
A22: LAIR (Lucro antes IR) | C22: =C20+C21 -> 1821.5121 | D22: =D20+D21 -> -865.28417 | E22: =E20+E21 -> 6420.0413 | F22: =F20+F21 -> 8494.1236 | G22: =G20+G21 -> 8444.2205 | H22: =H20+H21 -> 13741.582 | I22: =I20+I21 -> 14712.767 | J22: =J20+J21 -> 5399.4631 | ... AL22: =AL20+AL21 -> 28079.138 | AN22: =SUMIF($C$3:$AL$3,2025,$C22:$AL22) -> 131802.89 | AO22: =SUMIF($C$3:$AL$3,2026,$C22:$AL22) -> 97421.344 | AP22: =SUMIF($C$3:$AL$3,2027,$C22:$AL22) -> 70325.405
A23: (-) IR/CSLL | C23: =-MAX(0,C22)*Premissas!$B$5 -> -619.31412 | D23: =-MAX(0,D22)*Premissas!$B$5 -> 0 | E23: =-MAX(0,E22)*Premissas!$B$5 -> -2182.814 | F23: =-MAX(0,F22)*Premissas!$B$5 -> -2888.002 | G23: =-MAX(0,G22)*Premissas!$B$5 -> -2871.035 | H23: =-MAX(0,H22)*Premissas!$B$5 -> -4672.1379 | I23: =-MAX(0,I22)*Premissas!$B$5 -> -5002.3408 | J23: =-MAX(0,J22)*Premissas!$B$5 -> -1835.8175 | ... AL23: =-MAX(0,AL22)*Premissas!$B$5 -> -9546.9069 | AN23: =SUMIF($C$3:$AL$3,2025,$C23:$AL23) -> -45107.179 | AO23: =SUMIF($C$3:$AL$3,2026,$C23:$AL23) -> -39773.176 | AP23: =SUMIF($C$3:$AL$3,2027,$C23:$AL23) -> -34063.385
A24: Lucro Liquido | C24: =C22+C23 -> 1202.198 | D24: =D22+D23 -> -865.28417 | E24: =E22+E23 -> 4237.2272 | F24: =F22+F23 -> 5606.1216 | G24: =G22+G23 -> 5573.1855 | H24: =H22+H23 -> 9069.4441 | I24: =I22+I23 -> 9710.4263 | J24: =J22+J23 -> 3563.6457 | ... AL24: =AL22+AL23 -> 18532.231 | AN24: =SUMIF($C$3:$AL$3,2025,$C24:$AL24) -> 86695.71 | AO24: =SUMIF($C$3:$AL$3,2026,$C24:$AL24) -> 57648.168 | AP24: =SUMIF($C$3:$AL$3,2027,$C24:$AL24) -> 36262.021
A25: Margem Liquida % | C25: =IF(C6=0,0,C24/C6) -> 0.006873016 | D25: =IF(D6=0,0,D24/D6) -> -0.0050762032 | E25: =IF(E6=0,0,E24/E6) -> 0.022704491 | F25: =IF(F6=0,0,F24/F6) -> 0.029289402 | G25: =IF(G6=0,0,G24/G6) -> 0.028758225 | H25: =IF(H6=0,0,H24/H6) -> 0.043073272 | I25: =IF(I6=0,0,I24/I6) -> 0.045548553 | J25: =IF(J6=0,0,J24/J6) -> 0.018968628 | ... AL25: =IF(AL6=0,0,AL24/AL6) -> 0.064303123 | AN25: =IF(AN6=0,0,AN24/AN6) -> 0.035848701 | AO25: =IF(AO6=0,0,AO24/AO6) -> 0.022549226 | AP25: =IF(AP6=0,0,AP24/AP6) -> 0.013325549

Sheet Balanco_Consolidado
A1: BALANCO PATRIMONIAL CONSOLIDADO (mensal, R$)
A2: Linha | C2: 2025-01 | D2: 2025-02 | E2: 2025-03 | F2: 2025-04 | G2: 2025-05 | H2: 2025-06 | I2: 2025-07 | J2: 2025-08 | K2: 2025-09 | L2: 2025-10 | M2: 2025-11 | N2: 2025-12 | O2: 2026-01 | P2: 2026-02 | Q2: 2026-03 | R2: 2026-04 | S2: 2026-05 | T2: 2026-06 | U2: 2026-07 | V2: 2026-08 | W2: 2026-09 | X2: 2026-10 | Y2: 2026-11 | Z2: 2026-12 | AA2: 2027-01 | AB2: 2027-02 | AC2: 2027-03 | AD2: 2027-04 | AE2: 2027-05 | AF2: 2027-06 | AG2: 2027-07 | AH2: 2027-08 | AI2: 2027-09 | AJ2: 2027-10 | AK2: 2027-11 | AL2: 2027-12 | AN2: 2025 | AO2: 2026 | AP2: 2027
C3: 2025 | D3: 2025 | E3: 2025 | F3: 2025 | G3: 2025 | H3: 2025 | I3: 2025 | J3: 2025 | K3: 2025 | L3: 2025 | M3: 2025 | N3: 2025 | O3: 2026 | P3: 2026 | Q3: 2026 | R3: 2026 | S3: 2026 | T3: 2026 | U3: 2026 | V3: 2026 | W3: 2026 | X3: 2026 | Y3: 2026 | Z3: 2026 | AA3: 2027 | AB3: 2027 | AC3: 2027 | AD3: 2027 | AE3: 2027 | AF3: 2027 | AG3: 2027 | AH3: 2027 | AI3: 2027 | AJ3: 2027 | AK3: 2027 | AL3: 2027 | AN3: Total | AO3: Total | AP3: Total
A4: ATIVO
A5: Caixa e Equivalentes | C5: =DFC_Consolidado!C21 -> 448395.7 | D5: =DFC_Consolidado!D21 -> 454118.14 | E5: =DFC_Consolidado!E21 -> 448971.48 | F5: =DFC_Consolidado!F21 -> 453752.16 | G5: =DFC_Consolidado!G21 -> 451791.52 | H5: =DFC_Consolidado!H21 -> 430779.9 | I5: =DFC_Consolidado!I21 -> 405752.26 | J5: =DFC_Consolidado!J21 -> 378941.04 | ... AL5: =DFC_Consolidado!AL21 -> 387018.24 | AN5: =DFC_Consolidado!N21 -> 400785.67 | AO5: =DFC_Consolidado!Z21 -> 503671.04 | AP5: =DFC_Consolidado!AL21 -> 387018.24
A6: Contas a Receber | C6: =SUMIFS(Contas_Receber!$G:$G,Contas_Receber!$C:$C,C$2) -> 134689.72 | D6: =SUMIFS(Contas_Receber!$G:$G,Contas_Receber!$C:$C,D$2) -> 120751.33 | E6: =SUMIFS(Contas_Receber!$G:$G,Contas_Receber!$C:$C,E$2) -> 137288.64 | F6: =SUMIFS(Contas_Receber!$G:$G,Contas_Receber!$C:$C,F$2) -> 134627.58 | G6: =SUMIFS(Contas_Receber!$G:$G,Contas_Receber!$C:$C,G$2) -> 140529.43 | H6: =SUMIFS(Contas_Receber!$G:$G,Contas_Receber!$C:$C,H$2) -> 145382.58 | I6: =SUMIFS(Contas_Receber!$G:$G,Contas_Receber!$C:$C,I$2) -> 148041.69 | J6: =SUMIFS(Contas_Receber!$G:$G,Contas_Receber!$C:$C,J$2) -> 134050.9 | ... AL6: =SUMIFS(Contas_Receber!$G:$G,Contas_Receber!$C:$C,AL$2) -> 251071.58 | AN6: =SUMIF($C$3:$AL$3,2025,$C6:$AL6) -> 1740010.2 | AO6: =SUMIF($C$3:$AL$3,2026,$C6:$AL6) -> 2054628.9 | AP6: =SUMIF($C$3:$AL$3,2027,$C6:$AL6) -> 2446583.1
A7: Estoques | C7: =SUMIFS(Estoque!$G:$G,Estoque!$C:$C,C$2) -> 169799.38 | D7: =SUMIFS(Estoque!$G:$G,Estoque!$C:$C,D$2) -> 167734.2 | E7: =SUMIFS(Estoque!$G:$G,Estoque!$C:$C,E$2) -> 182327.48 | F7: =SUMIFS(Estoque!$G:$G,Estoque!$C:$C,F$2) -> 185651.9 | G7: =SUMIFS(Estoque!$G:$G,Estoque!$C:$C,G$2) -> 190437.99 | H7: =SUMIFS(Estoque!$G:$G,Estoque!$C:$C,H$2) -> 209970.7 | I7: =SUMIFS(Estoque!$G:$G,Estoque!$C:$C,I$2) -> 210217.62 | J7: =SUMIFS(Estoque!$G:$G,Estoque!$C:$C,J$2) -> 186204 | ... AL7: =SUMIFS(Estoque!$G:$G,Estoque!$C:$C,AL$2) -> 287759.5 | AN7: =SUMIF($C$3:$AL$3,2025,$C7:$AL7) -> 2375129.2 | AO7: =SUMIF($C$3:$AL$3,2026,$C7:$AL7) -> 2522982.2 | AP7: =SUMIF($C$3:$AL$3,2027,$C7:$AL7) -> 2694470.8
A8: Outros Ativos Circulantes | C8: =DRE_Consolidado!C6*Premissas!$B$13 -> 13993.251 | D8: =DRE_Consolidado!D6*Premissas!$B$13 -> 13636.714 | E8: =DRE_Consolidado!E6*Premissas!$B$13 -> 14930.006 | F8: =DRE_Consolidado!F6*Premissas!$B$13 -> 15312.355 | G8: =DRE_Consolidado!G6*Premissas!$B$13 -> 15503.559 | H8: =DRE_Consolidado!H6*Premissas!$B$13 -> 16844.681 | I8: =DRE_Consolidado!I6*Premissas!$B$13 -> 17055.078 | J8: =DRE_Consolidado!J6*Premissas!$B$13 -> 15029.64 | ... AL8: =DRE_Consolidado!AL6*Premissas!$B$13 -> 23056.088 | AN8: =SUMIF($C$3:$AL$3,2025,$C8:$AL8) -> 193470.24 | AO8: =SUMIF($C$3:$AL$3,2026,$C8:$AL8) -> 204523.8 | AP8: =SUMIF($C$3:$AL$3,2027,$C8:$AL8) -> 217699.22
A9: Ativo Circulante | C9: =SUM(C5:C8) -> 766878.05 | D9: =SUM(D5:D8) -> 756240.38 | E9: =SUM(E5:E8) -> 783517.61 | F9: =SUM(F5:F8) -> 789343.99 | G9: =SUM(G5:G8) -> 798262.51 | H9: =SUM(H5:H8) -> 802977.87 | I9: =SUM(I5:I8) -> 781066.65 | J9: =SUM(J5:J8) -> 714225.58 | ... AL9: =SUM(AL5:AL8) -> 948905.42 | AN9: =SUMIF($C$3:$AL$3,2025,$C9:$AL9) -> 9328904.7 | AO9: =SUMIF($C$3:$AL$3,2026,$C9:$AL9) -> 10156699 | AP9: =SUMIF($C$3:$AL$3,2027,$C9:$AL9) -> 10349987
A10: Imobilizado Liquido | C10: =Cronogramas!C9 -> 378435.2 | D10: =Cronogramas!D9 -> 376782.25 | E10: =Cronogramas!E9 -> 375348.46 | F10: =Cronogramas!F9 -> 373962.43 | G10: =Cronogramas!G9 -> 372588.03 | H10: =Cronogramas!H9 -> 401188.78 | I10: =Cronogramas!I9 -> 429552.32 | J10: =Cronogramas!J9 -> 457262.61 | ... AL10: =Cronogramas!AL9 -> 395967.56 | AN10: =SUMIF($C$3:$AL$3,2025,$C10:$AL10) -> 4974265.4 | AO10: =SUMIF($C$3:$AL$3,2026,$C10:$AL10) -> 5216557.2 | AP10: =SUMIF($C$3:$AL$3,2027,$C10:$AL10) -> 4891832.5
A11: Intangivel Liquido | C11: =Cronogramas!C12 -> 39333.333 | D11: =Cronogramas!D12 -> 38666.667 | E11: =Cronogramas!E12 -> 38000 | F11: =Cronogramas!F12 -> 37333.333 | G11: =Cronogramas!G12 -> 36666.667 | H11: =Cronogramas!H12 -> 36000 | I11: =Cronogramas!I12 -> 35333.333 | J11: =Cronogramas!J12 -> 34666.667 | ... AL11: =Cronogramas!AL12 -> 16000 | AN11: =SUMIF($C$3:$AL$3,2025,$C11:$AL11) -> 428000 | AO11: =SUMIF($C$3:$AL$3,2026,$C11:$AL11) -> 332000 | AP11: =SUMIF($C$3:$AL$3,2027,$C11:$AL11) -> 236000
A12: Ativo Nao Circulante | C12: =C10+C11 -> 417768.54 | D12: =D10+D11 -> 415448.92 | E12: =E10+E11 -> 413348.46 | F12: =F10+F11 -> 411295.77 | G12: =G10+G11 -> 409254.7 | H12: =H10+H11 -> 437188.78 | I12: =I10+I11 -> 464885.65 | J12: =J10+J11 -> 491929.27 | ... AL12: =AL10+AL11 -> 411967.56 | AN12: =SUMIF($C$3:$AL$3,2025,$C12:$AL12) -> 5402265.4 | AO12: =SUMIF($C$3:$AL$3,2026,$C12:$AL12) -> 5548557.2 | AP12: =SUMIF($C$3:$AL$3,2027,$C12:$AL12) -> 5127832.5
A13: ATIVO TOTAL | C13: =C9+C12 -> 1184646.6 | D13: =D9+D12 -> 1171689.3 | E13: =E9+E12 -> 1196866.1 | F13: =F9+F12 -> 1200639.8 | G13: =G9+G12 -> 1207517.2 | H13: =H9+H12 -> 1240166.6 | I13: =I9+I12 -> 1245952.3 | J13: =J9+J12 -> 1206154.9 | ... AL13: =AL9+AL12 -> 1360873 | AN13: =SUMIF($C$3:$AL$3,2025,$C13:$AL13) -> 14731170 | AO13: =SUMIF($C$3:$AL$3,2026,$C13:$AL13) -> 15705257 | AP13: =SUMIF($C$3:$AL$3,2027,$C13:$AL13) -> 15477819
A15: PASSIVO E PATRIMONIO LIQUIDO
A16: Fornecedores | C16: =SUMIFS(Contas_Pagar!$G:$G,Contas_Pagar!$C:$C,C$2) -> 138612.65 | D16: =SUMIFS(Contas_Pagar!$G:$G,Contas_Pagar!$C:$C,D$2) -> 138606.51 | E16: =SUMIFS(Contas_Pagar!$G:$G,Contas_Pagar!$C:$C,E$2) -> 150583.08 | F16: =SUMIFS(Contas_Pagar!$G:$G,Contas_Pagar!$C:$C,F$2) -> 153637.34 | G16: =SUMIFS(Contas_Pagar!$G:$G,Contas_Pagar!$C:$C,G$2) -> 157194.9 | H16: =SUMIFS(Contas_Pagar!$G:$G,Contas_Pagar!$C:$C,H$2) -> 173293.47 | I16: =SUMIFS(Contas_Pagar!$G:$G,Contas_Pagar!$C:$C,I$2) -> 173846.28 | J16: =SUMIFS(Contas_Pagar!$G:$G,Contas_Pagar!$C:$C,J$2) -> 153791.36 | ... AL16: =SUMIFS(Contas_Pagar!$G:$G,Contas_Pagar!$C:$C,AL$2) -> 237631.17 | AN16: =SUMIF($C$3:$AL$3,2025,$C16:$AL16) -> 1959414.5 | AO16: =SUMIF($C$3:$AL$3,2026,$C16:$AL16) -> 2075363.8 | AP16: =SUMIF($C$3:$AL$3,2027,$C16:$AL16) -> 2216816.1
A17: Emprestimos Curto Prazo | C17: =Cronogramas!C19 -> 140000 | D17: =Cronogramas!D19 -> 140000 | E17: =Cronogramas!E19 -> 140000 | F17: =Cronogramas!F19 -> 140000 | G17: =Cronogramas!G19 -> 140000 | H17: =Cronogramas!H19 -> 140000 | I17: =Cronogramas!I19 -> 140000 | J17: =Cronogramas!J19 -> 140000 | ... AL17: =Cronogramas!AL19 -> 180000 | AN17: =SUMIF($C$3:$AL$3,2025,$C17:$AL17) -> 1680000 | AO17: =SUMIF($C$3:$AL$3,2026,$C17:$AL17) -> 2640000 | AP17: =SUMIF($C$3:$AL$3,2027,$C17:$AL17) -> 2560000
A18: Obrigacoes Fiscais | C18: =-DRE_Consolidado!C5-DRE_Consolidado!C23 -> 87085.774 | D18: =-DRE_Consolidado!D5-DRE_Consolidado!D23 -> 80445.58 | E18: =-DRE_Consolidado!E5-DRE_Consolidado!E23 -> 92791.944 | F18: =-DRE_Consolidado!F5-DRE_Consolidado!F23 -> 92427.312 | G18: =-DRE_Consolidado!G5-DRE_Consolidado!G23 -> 94935.015 | H18: =-DRE_Consolidado!H5-DRE_Consolidado!H23 -> 105740.03 | I18: =-DRE_Consolidado!I5-DRE_Consolidado!I23 -> 105999.45 | J18: =-DRE_Consolidado!J5-DRE_Consolidado!J23 -> 90225.077 | ... AL18: =-DRE_Consolidado!AL5-DRE_Consolidado!AL23 -> 147630.96 | AN18: =SUMIF($C$3:$AL$3,2025,$C18:$AL18) -> 1201491.8 | AO18: =SUMIF($C$3:$AL$3,2026,$C18:$AL18) -> 1246604.4 | AP18: =SUMIF($C$3:$AL$3,2027,$C18:$AL18) -> 1345369.9
A19: Obrigacoes Trabalhistas | C19: =-DRE_Consolidado!C10*Premissas!$B$15 -> 15254.4 | D19: =-DRE_Consolidado!D10*Premissas!$B$15 -> 15254.4 | E19: =-DRE_Consolidado!E10*Premissas!$B$15 -> 15254.4 | F19: =-DRE_Consolidado!F10*Premissas!$B$15 -> 15254.4 | G19: =-DRE_Consolidado!G10*Premissas!$B$15 -> 15254.4 | H19: =-DRE_Consolidado!H10*Premissas!$B$15 -> 15254.4 | I19: =-DRE_Consolidado!I10*Premissas!$B$15 -> 15254.4 | J19: =-DRE_Consolidado!J10*Premissas!$B$15 -> 15254.4 | ... AL19: =-DRE_Consolidado!AL10*Premissas!$B$15 -> 19488 | AN19: =SUMIF($C$3:$AL$3,2025,$C19:$AL19) -> 183052.8 | AO19: =SUMIF($C$3:$AL$3,2026,$C19:$AL19) -> 204019.2 | AP19: =SUMIF($C$3:$AL$3,2027,$C19:$AL19) -> 233856
A20: Outros Passivos Circulantes | C20: =DRE_Consolidado!C6*Premissas!$B$14 -> 17491.564 | D20: =DRE_Consolidado!D6*Premissas!$B$14 -> 17045.893 | E20: =DRE_Consolidado!E6*Premissas!$B$14 -> 18662.507 | F20: =DRE_Consolidado!F6*Premissas!$B$14 -> 19140.444 | G20: =DRE_Consolidado!G6*Premissas!$B$14 -> 19379.449 | H20: =DRE_Consolidado!H6*Premissas!$B$14 -> 21055.851 | I20: =DRE_Consolidado!I6*Premissas!$B$14 -> 21318.847 | J20: =DRE_Consolidado!J6*Premissas!$B$14 -> 18787.05 | ... AL20: =DRE_Consolidado!AL6*Premissas!$B$14 -> 28820.11 | AN20: =SUMIF($C$3:$AL$3,2025,$C20:$AL20) -> 241837.8 | AO20: =SUMIF($C$3:$AL$3,2026,$C20:$AL20) -> 255654.75 | AP20: =SUMIF($C$3:$AL$3,2027,$C20:$AL20) -> 272124.03
A21: Passivo Circulante | C21: =SUM(C16:C20) -> 398444.39 | D21: =SUM(D16:D20) -> 391352.39 | E21: =SUM(E16:E20) -> 417291.93 | F21: =SUM(F16:F20) -> 420459.5 | G21: =SUM(G16:G20) -> 426763.76 | H21: =SUM(H16:H20) -> 455343.75 | I21: =SUM(I16:I20) -> 456418.98 | J21: =SUM(J16:J20) -> 418057.89 | ... AL21: =SUM(AL16:AL20) -> 613570.24 | AN21: =SUMIF($C$3:$AL$3,2025,$C21:$AL21) -> 5265796.9 | AO21: =SUMIF($C$3:$AL$3,2026,$C21:$AL21) -> 6421642.1 | AP21: =SUMIF($C$3:$AL$3,2027,$C21:$AL21) -> 6628166
A22: Emprestimos Longo Prazo | C22: =Cronogramas!C20 -> 185000 | D22: =Cronogramas!D20 -> 180000 | E22: =Cronogramas!E20 -> 175000 | F22: =Cronogramas!F20 -> 170000 | G22: =Cronogramas!G20 -> 165000 | H22: =Cronogramas!H20 -> 160000 | I22: =Cronogramas!I20 -> 155000 | J22: =Cronogramas!J20 -> 150000 | ... AL22: =Cronogramas!AL20 -> 10000 | AN22: =SUMIF($C$3:$AL$3,2025,$C22:$AL22) -> 1890000 | AO22: =SUMIF($C$3:$AL$3,2026,$C22:$AL22) -> 1170000 | AP22: =SUMIF($C$3:$AL$3,2027,$C22:$AL22) -> 450000
A23: Passivo Nao Circulante | C23: =C22 -> 185000 | D23: =D22 -> 180000 | E23: =E22 -> 175000 | F23: =F22 -> 170000 | G23: =G22 -> 165000 | H23: =H22 -> 160000 | I23: =I22 -> 155000 | J23: =J22 -> 150000 | ... AL23: =AL22 -> 10000 | AN23: =SUMIF($C$3:$AL$3,2025,$C23:$AL23) -> 1890000 | AO23: =SUMIF($C$3:$AL$3,2026,$C23:$AL23) -> 1170000 | AP23: =SUMIF($C$3:$AL$3,2027,$C23:$AL23) -> 450000
A24: (memo) Dividendos Pagos no Mes | C24: =0 -> 0 | D24: =0 -> 0 | E24: =0 -> 0 | F24: =0 -> 0 | G24: =0 -> 0 | H24: =0 -> 0 | I24: =0 -> 0 | J24: =0 -> 0 | ... Q24: =0 -> 0 | R24: =DRE_Consolidado!AN24*Premissas!$B$12 -> 26008.713 | S24: =0 -> 0 | T24: =0 -> 0 | U24: =0 -> 0 | V24: =0 -> 0 | W24: =0 -> 0 | X24: =0 -> 0 | Y24: =0 -> 0 | Z24: =0 -> 0 | ... AC24: =0 -> 0 | AD24: =DRE_Consolidado!AO24*Premissas!$B$12 -> 17294.451 | AE24: =0 -> 0 | AF24: =0 -> 0 | AG24: =0 -> 0 | AH24: =0 -> 0 | AI24: =0 -> 0 | AJ24: =0 -> 0 | AK24: =0 -> 0 | AL24: =0 -> 0 | AN24: =SUMIF($C$3:$AL$3,2025,$C24:$AL24) -> 0 | AO24: =SUMIF($C$3:$AL$3,2026,$C24:$AL24) -> 26008.713 | AP24: =SUMIF($C$3:$AL$3,2027,$C24:$AL24) -> 17294.451
A25: Capital Social | C25: =Premissas!$B$32 -> 400000 | D25: =Premissas!$B$32 -> 400000 | E25: =Premissas!$B$32 -> 400000 | F25: =Premissas!$B$32 -> 400000 | G25: =Premissas!$B$32 -> 400000 | H25: =Premissas!$B$32 -> 400000 | I25: =Premissas!$B$32 -> 400000 | J25: =Premissas!$B$32 -> 400000 | ... AL25: =Premissas!$B$32 -> 400000 | AN25: =SUMIF($C$3:$AL$3,2025,$C25:$AL25) -> 4800000 | AO25: =SUMIF($C$3:$AL$3,2026,$C25:$AL25) -> 4800000 | AP25: =SUMIF($C$3:$AL$3,2027,$C25:$AL25) -> 4800000
A26: Lucros Acumulados | C26: =Premissas!$B$33+DRE_Consolidado!C24-C24 -> 201202.2 | D26: =C26+DRE_Consolidado!D24-D24 -> 200336.91 | E26: =D26+DRE_Consolidado!E24-E24 -> 204574.14 | F26: =E26+DRE_Consolidado!F24-F24 -> 210180.26 | G26: =F26+DRE_Consolidado!G24-G24 -> 215753.45 | H26: =G26+DRE_Consolidado!H24-H24 -> 224822.89 | I26: =H26+DRE_Consolidado!I24-I24 -> 234533.32 | J26: =I26+DRE_Consolidado!J24-J24 -> 238096.96 | K26: =J26+DRE_Consolidado!K24-K24 -> 242579.36 | ... AL26: =AK26+DRE_Consolidado!AL24-AL24 -> 337302.74 | AN26: =N26 -> 286695.71 | AO26: =Z26 -> 318335.17 | AP26: =AL26 -> 337302.74
A27: Patrimonio Liquido | C27: =C25+C26 -> 601202.2 | D27: =D25+D26 -> 600336.91 | E27: =E25+E26 -> 604574.14 | F27: =F25+F26 -> 610180.26 | G27: =G25+G26 -> 615753.45 | H27: =H25+H26 -> 624822.89 | I27: =I25+I26 -> 634533.32 | J27: =J25+J26 -> 638096.96 | ... AL27: =AL25+AL26 -> 737302.74 | AN27: =SUMIF($C$3:$AL$3,2025,$C27:$AL27) -> 7575373.2 | AO27: =SUMIF($C$3:$AL$3,2026,$C27:$AL27) -> 8113614.5 | AP27: =SUMIF($C$3:$AL$3,2027,$C27:$AL27) -> 8399653.4
A28: PASSIVO + PL TOTAL | C28: =C21+C23+C27 -> 1184646.6 | D28: =D21+D23+D27 -> 1171689.3 | E28: =E21+E23+E27 -> 1196866.1 | F28: =F21+F23+F27 -> 1200639.8 | G28: =G21+G23+G27 -> 1207517.2 | H28: =H21+H23+H27 -> 1240166.6 | I28: =I21+I23+I27 -> 1245952.3 | J28: =J21+J23+J27 -> 1206154.9 | ... AL28: =AL21+AL23+AL27 -> 1360873 | AN28: =SUMIF($C$3:$AL$3,2025,$C28:$AL28) -> 14731170 | AO28: =SUMIF($C$3:$AL$3,2026,$C28:$AL28) -> 15705257 | AP28: =SUMIF($C$3:$AL$3,2027,$C28:$AL28) -> 15477819
A29: CHECAGEM (Ativo - Passivo-PL) | C29: =C13-C28 -> 0 | D29: =D13-D28 -> 0 | E29: =E13-E28 -> 0 | F29: =F13-F28 -> 0 | G29: =G13-G28 -> 0 | H29: =H13-H28 -> 0 | I29: =I13-I28 -> 0 | J29: =J13-J28 -> 0 | ... AL29: =AL13-AL28 -> 0 | AN29: =SUMIF($C$3:$AL$3,2025,$C29:$AL29) -> 0 | AO29: =SUMIF($C$3:$AL$3,2026,$C29:$AL29) -> 0 | AP29: =SUMIF($C$3:$AL$3,2027,$C29:$AL29) -> 0

Sheet DFC_Consolidado
A1: DEMONSTRACAO DE FLUXO DE CAIXA - Metodo Indireto (mensal, R$)
A2: Linha | C2: 2025-01 | D2: 2025-02 | E2: 2025-03 | F2: 2025-04 | G2: 2025-05 | H2: 2025-06 | I2: 2025-07 | J2: 2025-08 | K2: 2025-09 | L2: 2025-10 | M2: 2025-11 | N2: 2025-12 | O2: 2026-01 | P2: 2026-02 | Q2: 2026-03 | R2: 2026-04 | S2: 2026-05 | T2: 2026-06 | U2: 2026-07 | V2: 2026-08 | W2: 2026-09 | X2: 2026-10 | Y2: 2026-11 | Z2: 2026-12 | AA2: 2027-01 | AB2: 2027-02 | AC2: 2027-03 | AD2: 2027-04 | AE2: 2027-05 | AF2: 2027-06 | AG2: 2027-07 | AH2: 2027-08 | AI2: 2027-09 | AJ2: 2027-10 | AK2: 2027-11 | AL2: 2027-12 | AN2: 2025 | AO2: 2026 | AP2: 2027
C3: 2025 | D3: 2025 | E3: 2025 | F3: 2025 | G3: 2025 | H3: 2025 | I3: 2025 | J3: 2025 | K3: 2025 | L3: 2025 | M3: 2025 | N3: 2025 | O3: 2026 | P3: 2026 | Q3: 2026 | R3: 2026 | S3: 2026 | T3: 2026 | U3: 2026 | V3: 2026 | W3: 2026 | X3: 2026 | Y3: 2026 | Z3: 2026 | AA3: 2027 | AB3: 2027 | AC3: 2027 | AD3: 2027 | AE3: 2027 | AF3: 2027 | AG3: 2027 | AH3: 2027 | AI3: 2027 | AJ3: 2027 | AK3: 2027 | AL3: 2027 | AN3: Total | AO3: Total | AP3: Total
A4: Lucro Liquido | C4: =DRE_Consolidado!C24 -> 1202.198 | D4: =DRE_Consolidado!D24 -> -865.28417 | E4: =DRE_Consolidado!E24 -> 4237.2272 | F4: =DRE_Consolidado!F24 -> 5606.1216 | G4: =DRE_Consolidado!G24 -> 5573.1855 | H4: =DRE_Consolidado!H24 -> 9069.4441 | I4: =DRE_Consolidado!I24 -> 9710.4263 | J4: =DRE_Consolidado!J24 -> 3563.6457 | ... AL4: =DRE_Consolidado!AL24 -> 18532.231 | AN4: =SUMIF($C$3:$AL$3,2025,$C4:$AL4) -> 86695.71 | AO4: =SUMIF($C$3:$AL$3,2026,$C4:$AL4) -> 57648.168 | AP4: =SUMIF($C$3:$AL$3,2027,$C4:$AL4) -> 36262.021
A5: (+) Depreciacao e Amortizacao | C5: =Cronogramas!C7+Cronogramas!C11 -> 4855.1978 | D5: =Cronogramas!D7+Cronogramas!D11 -> 4876.5052 | E5: =Cronogramas!E7+Cronogramas!E11 -> 4899.8333 | F5: =Cronogramas!F7+Cronogramas!F11 -> 4923.7588 | G5: =Cronogramas!G7+Cronogramas!G11 -> 4947.9832 | H5: =Cronogramas!H7+Cronogramas!H11 -> 5224.303 | I5: =Cronogramas!I7+Cronogramas!I11 -> 5500.9515 | J5: =Cronogramas!J7+Cronogramas!J11 -> 5774.4353 | ... AL5: =Cronogramas!AL7+Cronogramas!AL11 -> 6545.3541 | AN5: =SUMIF($C$3:$AL$3,2025,$C5:$AL5) -> 64364.765 | AO5: =SUMIF($C$3:$AL$3,2026,$C5:$AL5) -> 72573.103 | AP5: =SUMIF($C$3:$AL$3,2027,$C5:$AL5) -> 76537.059
A6: (-) Var. Contas a Receber | C6: =-(Balanco_Consolidado!C6-Premissas!$B$18) -> -4689.7217 | D6: =-(Balanco_Consolidado!D6-Balanco_Consolidado!C6) -> 13938.393 | E6: =-(Balanco_Consolidado!E6-Balanco_Consolidado!D6) -> -16537.316 | F6: =-(Balanco_Consolidado!F6-Balanco_Consolidado!E6) -> 2661.0673 | G6: =-(Balanco_Consolidado!G6-Balanco_Consolidado!F6) -> -5901.8567 | H6: =-(Balanco_Consolidado!H6-Balanco_Consolidado!G6) -> -4853.1493 | I6: =-(Balanco_Consolidado!I6-Balanco_Consolidado!H6) -> -2659.1057 | J6: =-(Balanco_Consolidado!J6-Balanco_Consolidado!I6) -> 13990.787 | K6: =-(Balanco_Consolidado!K6-Balanco_Consolidado!J6) -> -10965.034 | ... AL6: =-(Balanco_Consolidado!AL6-Balanco_Consolidado!AK6) -> -11187.887 | AN6: =SUMIF($C$3:$AL$3,2025,$C6:$AL6) -> -51941.238 | AO6: =SUMIF($C$3:$AL$3,2026,$C6:$AL6) -> -27852.784 | AP6: =SUMIF($C$3:$AL$3,2027,$C6:$AL6) -> -41277.559
A7: (-) Var. Estoques | C7: =-(Balanco_Consolidado!C7-Premissas!$B$19) -> 10200.622 | D7: =-(Balanco_Consolidado!D7-Balanco_Consolidado!C7) -> 2065.1749 | E7: =-(Balanco_Consolidado!E7-Balanco_Consolidado!D7) -> -14593.278 | F7: =-(Balanco_Consolidado!F7-Balanco_Consolidado!E7) -> -3324.419 | G7: =-(Balanco_Consolidado!G7-Balanco_Consolidado!F7) -> -4786.0923 | H7: =-(Balanco_Consolidado!H7-Balanco_Consolidado!G7) -> -19532.706 | I7: =-(Balanco_Consolidado!I7-Balanco_Consolidado!H7) -> -246.92437 | J7: =-(Balanco_Consolidado!J7-Balanco_Consolidado!I7) -> 24013.626 | K7: =-(Balanco_Consolidado!K7-Balanco_Consolidado!J7) -> -53.1437 | ... AL7: =-(Balanco_Consolidado!AL7-Balanco_Consolidado!AK7) -> -20592.984 | AN7: =SUMIF($C$3:$AL$3,2025,$C7:$AL7) -> -68556.416 | AO7: =SUMIF($C$3:$AL$3,2026,$C7:$AL7) -> -20523.768 | AP7: =SUMIF($C$3:$AL$3,2027,$C7:$AL7) -> -18679.321
A8: (-) Var. Outros Ativos Circ. | C8: =-(Balanco_Consolidado!C8-Premissas!$B$20) -> 2006.7488 | D8: =-(Balanco_Consolidado!D8-Balanco_Consolidado!C8) -> 356.5368 | E8: =-(Balanco_Consolidado!E8-Balanco_Consolidado!D8) -> -1293.2912 | F8: =-(Balanco_Consolidado!F8-Balanco_Consolidado!E8) -> -382.3496 | G8: =-(Balanco_Consolidado!G8-Balanco_Consolidado!F8) -> -191.204 | H8: =-(Balanco_Consolidado!H8-Balanco_Consolidado!G8) -> -1341.1216 | I8: =-(Balanco_Consolidado!I8-Balanco_Consolidado!H8) -> -210.3968 | J8: =-(Balanco_Consolidado!J8-Balanco_Consolidado!I8) -> 2025.4376 | K8: =-(Balanco_Consolidado!K8-Balanco_Consolidado!J8) -> -195.4848 | ... AL8: =-(Balanco_Consolidado!AL8-Balanco_Consolidado!AK8) -> -1669.3598 | AN8: =SUMIF($C$3:$AL$3,2025,$C8:$AL8) -> -4266.7496 | AO8: =SUMIF($C$3:$AL$3,2026,$C8:$AL8) -> -1396.1424 | AP8: =SUMIF($C$3:$AL$3,2027,$C8:$AL8) -> -1393.1961
A9: (+) Var. Fornecedores | C9: =(Balanco_Consolidado!C16-Premissas!$B$24) -> -11387.35 | D9: =(Balanco_Consolidado!D16-Balanco_Consolidado!C16) -> -6.1367333 | E9: =(Balanco_Consolidado!E16-Balanco_Consolidado!D16) -> 11976.566 | F9: =(Balanco_Consolidado!F16-Balanco_Consolidado!E16) -> 3054.2589 | G9: =(Balanco_Consolidado!G16-Balanco_Consolidado!F16) -> 3557.5574 | H9: =(Balanco_Consolidado!H16-Balanco_Consolidado!G16) -> 16098.573 | I9: =(Balanco_Consolidado!I16-Balanco_Consolidado!H16) -> 552.8142 | J9: =(Balanco_Consolidado!J16-Balanco_Consolidado!I16) -> -20054.924 | K9: =(Balanco_Consolidado!K16-Balanco_Consolidado!J16) -> -1166.5077 | ... AL9: =(Balanco_Consolidado!AL16-Balanco_Consolidado!AK16) -> 17746.329 | AN9: =SUMIF($C$3:$AL$3,2025,$C9:$AL9) -> 54938.123 | AO9: =SUMIF($C$3:$AL$3,2026,$C9:$AL9) -> 17279.659 | AP9: =SUMIF($C$3:$AL$3,2027,$C9:$AL9) -> 15413.388
A10: (+) Var. Obrigacoes Fiscais | C10: =(Balanco_Consolidado!C18-Premissas!$B$25) -> -7914.2259 | D10: =(Balanco_Consolidado!D18-Balanco_Consolidado!C18) -> -6640.1941 | E10: =(Balanco_Consolidado!E18-Balanco_Consolidado!D18) -> 12346.364 | F10: =(Balanco_Consolidado!F18-Balanco_Consolidado!E18) -> -364.632 | G10: =(Balanco_Consolidado!G18-Balanco_Consolidado!F18) -> 2507.7029 | H10: =(Balanco_Consolidado!H18-Balanco_Consolidado!G18) -> 10805.013 | I10: =(Balanco_Consolidado!I18-Balanco_Consolidado!H18) -> 259.42299 | J10: =(Balanco_Consolidado!J18-Balanco_Consolidado!I18) -> -15774.373 | K10: =(Balanco_Consolidado!K18-Balanco_Consolidado!J18) -> 7732.4336 | ... AL10: =(Balanco_Consolidado!AL18-Balanco_Consolidado!AK18) -> 10974.353 | AN10: =SUMIF($C$3:$AL$3,2025,$C10:$AL10) -> 36239.306 | AO10: =SUMIF($C$3:$AL$3,2026,$C10:$AL10) -> 6021.6884 | AP10: =SUMIF($C$3:$AL$3,2027,$C10:$AL10) -> 10369.966
A11: (+) Var. Obrigacoes Trabalhistas | C11: =(Balanco_Consolidado!C19-Premissas!$B$26) -> 254.4 | D11: =(Balanco_Consolidado!D19-Balanco_Consolidado!C19) -> 0 | E11: =(Balanco_Consolidado!E19-Balanco_Consolidado!D19) -> 0 | F11: =(Balanco_Consolidado!F19-Balanco_Consolidado!E19) -> 0 | G11: =(Balanco_Consolidado!G19-Balanco_Consolidado!F19) -> 0 | H11: =(Balanco_Consolidado!H19-Balanco_Consolidado!G19) -> 0 | I11: =(Balanco_Consolidado!I19-Balanco_Consolidado!H19) -> 0 | J11: =(Balanco_Consolidado!J19-Balanco_Consolidado!I19) -> 0 | K11: =(Balanco_Consolidado!K19-Balanco_Consolidado!J19) -> 0 | ... AL11: =(Balanco_Consolidado!AL19-Balanco_Consolidado!AK19) -> 0 | AN11: =SUMIF($C$3:$AL$3,2025,$C11:$AL11) -> 254.4 | AO11: =SUMIF($C$3:$AL$3,2026,$C11:$AL11) -> 1747.2 | AP11: =SUMIF($C$3:$AL$3,2027,$C11:$AL11) -> 2486.4
A12: (+) Var. Outros Passivos Circ. | C12: =(Balanco_Consolidado!C20-Premissas!$B$27) -> -2508.436 | D12: =(Balanco_Consolidado!D20-Balanco_Consolidado!C20) -> -445.671 | E12: =(Balanco_Consolidado!E20-Balanco_Consolidado!D20) -> 1616.614 | F12: =(Balanco_Consolidado!F20-Balanco_Consolidado!E20) -> 477.937 | G12: =(Balanco_Consolidado!G20-Balanco_Consolidado!F20) -> 239.005 | H12: =(Balanco_Consolidado!H20-Balanco_Consolidado!G20) -> 1676.402 | I12: =(Balanco_Consolidado!I20-Balanco_Consolidado!H20) -> 262.996 | J12: =(Balanco_Consolidado!J20-Balanco_Consolidado!I20) -> -2531.797 | K12: =(Balanco_Consolidado!K20-Balanco_Consolidado!J20) -> 244.356 | ... AL12: =(Balanco_Consolidado!AL20-Balanco_Consolidado!AK20) -> 2086.6998 | AN12: =SUMIF($C$3:$AL$3,2025,$C12:$AL12) -> 5333.437 | AO12: =SUMIF($C$3:$AL$3,2026,$C12:$AL12) -> 1745.178 | AP12: =SUMIF($C$3:$AL$3,2027,$C12:$AL12) -> 1741.4951
A13: (=) Fluxo de Caixa Operacional | C13: =SUM(C4:C12) -> -7980.5669 | D13: =SUM(D4:D12) -> 13279.324 | E13: =SUM(E4:E12) -> 2652.7199 | F13: =SUM(F4:F12) -> 12651.743 | G13: =SUM(G4:G12) -> 5946.2811 | H13: =SUM(H4:H12) -> 17146.758 | I13: =SUM(I4:I12) -> 13170.184 | J13: =SUM(J4:J12) -> 11006.837 | ... AL13: =SUM(AL4:AL12) -> 22434.736 | AN13: =SUMIF($C$3:$AL$3,2025,$C13:$AL13) -> 123061.34 | AO13: =SUMIF($C$3:$AL$3,2026,$C13:$AL13) -> 107242.3 | AP13: =SUMIF($C$3:$AL$3,2027,$C13:$AL13) -> 81460.253
A14: (-) Capex | C14: =-Cronogramas!C5 -> -2623.7346 | D14: =-Cronogramas!D5 -> -2556.8839 | E14: =-Cronogramas!E5 -> -2799.376 | F14: =-Cronogramas!F5 -> -2871.0666 | G14: =-Cronogramas!G5 -> -2906.9174 | H14: =-Cronogramas!H5 -> -33158.378 | I14: =-Cronogramas!I5 -> -33197.827 | J14: =-Cronogramas!J5 -> -32818.058 | ... AL14: =-Cronogramas!AL5 -> -4323.0165 | AN14: =SUMIF($C$3:$AL$3,2025,$C14:$AL14) -> -126275.67 | AO14: =SUMIF($C$3:$AL$3,2026,$C14:$AL14) -> -38348.213 | AP14: =SUMIF($C$3:$AL$3,2027,$C14:$AL14) -> -40818.604
A15: (=) Fluxo de Caixa de Investimento | C15: =C14 -> -2623.7346 | D15: =D14 -> -2556.8839 | E15: =E14 -> -2799.376 | F15: =F14 -> -2871.0666 | G15: =G14 -> -2906.9174 | H15: =H14 -> -33158.378 | I15: =I14 -> -33197.827 | J15: =J14 -> -32818.058 | ... AL15: =AL14 -> -4323.0165 | AN15: =SUMIF($C$3:$AL$3,2025,$C15:$AL15) -> -126275.67 | AO15: =SUMIF($C$3:$AL$3,2026,$C15:$AL15) -> -38348.213 | AP15: =SUMIF($C$3:$AL$3,2027,$C15:$AL15) -> -40818.604
A16: (+/-) Captacao/Amortizacao de Divida | C16: =(Cronogramas!C18-(Premissas!$B$28+Premissas!$B$29)) -> -5000 | D16: =(Cronogramas!D18-Cronogramas!C18) -> -5000 | E16: =(Cronogramas!E18-Cronogramas!D18) -> -5000 | F16: =(Cronogramas!F18-Cronogramas!E18) -> -5000 | G16: =(Cronogramas!G18-Cronogramas!F18) -> -5000 | H16: =(Cronogramas!H18-Cronogramas!G18) -> -5000 | I16: =(Cronogramas!I18-Cronogramas!H18) -> -5000 | J16: =(Cronogramas!J18-Cronogramas!I18) -> -5000 | K16: =(Cronogramas!K18-Cronogramas!J18) -> -5000 | ... AL16: =(Cronogramas!AL18-Cronogramas!AK18) -> -10000 | AN16: =SUMIF($C$3:$AL$3,2025,$C16:$AL16) -> -60000 | AO16: =SUMIF($C$3:$AL$3,2026,$C16:$AL16) -> 60000 | AP16: =SUMIF($C$3:$AL$3,2027,$C16:$AL16) -> -140000
A17: (-) Dividendos | C17: =-Balanco_Consolidado!C24 -> 0 | D17: =-Balanco_Consolidado!D24 -> 0 | E17: =-Balanco_Consolidado!E24 -> 0 | F17: =-Balanco_Consolidado!F24 -> 0 | G17: =-Balanco_Consolidado!G24 -> 0 | H17: =-Balanco_Consolidado!H24 -> 0 | I17: =-Balanco_Consolidado!I24 -> 0 | J17: =-Balanco_Consolidado!J24 -> 0 | ... AL17: =-Balanco_Consolidado!AL24 -> 0 | AN17: =SUMIF($C$3:$AL$3,2025,$C17:$AL17) -> 0 | AO17: =SUMIF($C$3:$AL$3,2026,$C17:$AL17) -> -26008.713 | AP17: =SUMIF($C$3:$AL$3,2027,$C17:$AL17) -> -17294.451
A18: (=) Fluxo de Caixa de Financiamento | C18: =C16+C17 -> -5000 | D18: =D16+D17 -> -5000 | E18: =E16+E17 -> -5000 | F18: =F16+F17 -> -5000 | G18: =G16+G17 -> -5000 | H18: =H16+H17 -> -5000 | I18: =I16+I17 -> -5000 | J18: =J16+J17 -> -5000 | ... AL18: =AL16+AL17 -> -10000 | AN18: =SUMIF($C$3:$AL$3,2025,$C18:$AL18) -> -60000 | AO18: =SUMIF($C$3:$AL$3,2026,$C18:$AL18) -> 33991.287 | AP18: =SUMIF($C$3:$AL$3,2027,$C18:$AL18) -> -157294.45
A19: Variacao de Caixa | C19: =C13+C15+C18 -> -15604.302 | D19: =D13+D15+D18 -> 5722.4396 | E19: =E13+E15+E18 -> -5146.6561 | F19: =F13+F15+F18 -> 4780.6765 | G19: =G13+G15+G18 -> -1960.6363 | H19: =H13+H15+H18 -> -21011.62 | I19: =I13+I15+I18 -> -25027.643 | J19: =J13+J15+J18 -> -26811.221 | ... AL19: =AL13+AL15+AL18 -> 8111.7193 | AN19: =SUMIF($C$3:$AL$3,2025,$C19:$AL19) -> -63214.333 | AO19: =SUMIF($C$3:$AL$3,2026,$C19:$AL19) -> 102885.38 | AP19: =SUMIF($C$3:$AL$3,2027,$C19:$AL19) -> -116652.8
A20: Caixa Inicial | C20: =Premissas!$B$35 -> 464000 | D20: =C21 -> 448395.7 | E20: =D21 -> 454118.14 | F20: =E21 -> 448971.48 | G20: =F21 -> 453752.16 | H20: =G21 -> 451791.52 | I20: =H21 -> 430779.9 | J20: =I21 -> 405752.26 | K20: =J21 -> 378941.04 | ... AL20: =AK21 -> 378906.52 | AN20: =C20 -> 464000 | AO20: =O20 -> 400785.67 | AP20: =AA20 -> 503671.04
A21: Caixa Final | C21: =C20+C19 -> 448395.7 | D21: =D20+D19 -> 454118.14 | E21: =E20+E19 -> 448971.48 | F21: =F20+F19 -> 453752.16 | G21: =G20+G19 -> 451791.52 | H21: =H20+H19 -> 430779.9 | I21: =I20+I19 -> 405752.26 | J21: =J20+J19 -> 378941.04 | ... AL21: =AL20+AL19 -> 387018.24 | AN21: =N21 -> 400785.67 | AO21: =Z21 -> 503671.04 | AP21: =AL21 -> 387018.24

Sheet KPIs_Mensais
A1: Ano | B1: Mes | C1: ChaveMes | D1: DataRef | E1: Receita Bruta | F1: Receita Liquida | G1: Cresc. MoM % | H1: Cresc. YoY % | I1: Margem Bruta % | J1: Margem EBITDA % | K1: Margem Liquida % | L1: EBITDA | M1: Lucro Liquido | N1: DSO (dias) | O1: DIO (dias) | P1: DPO (dias) | Q1: Ciclo Caixa (dias) | R1: Liquidez Corrente | S1: Divida Liquida | T1: Div.Liq/EBITDA LTM | U1: Cobertura Juros | V1: ROIC LTM % | W1: FCO do Mes | X1: Capital Giro Liq.
A2: 2025 | B2: 1 | C2: 2025-01 | D2: 45658 | E2: =DRE_Consolidado!C4 -> 261382.1 | F2: =DRE_Consolidado!C6 -> 174915.64 | I2: =DRE_Consolidado!C9 -> 0.44495308 | J2: =DRE_Consolidado!C18 -> 0.044482643 | K2: =DRE_Consolidado!C25 -> 0.006873016 | L2: =DRE_Consolidado!C17 -> 7780.7099 | M2: =DRE_Consolidado!C24 -> 1202.198 | N2: =IF(DRE_Consolidado!C6=0,0,Balanco_Consolidado!C6/DRE_Consolidado!C6*30) -> 23.100802 | O2: =IF(DRE_Consolidado!C7=0,0,Balanco_Consolidado!C7/(-DRE_Consolidado!C7)*30) -> 52.468544 | P2: =IF(DRE_Consolidado!C7=0,0,Balanco_Consolidado!C16/(-DRE_Consolidado!C7)*30) -> 42.831746 | Q2: =N2+O2-P2 -> 32.7376 | R2: =IF(Balanco_Consolidado!C21=0,0,Balanco_Consolidado!C9/Balanco_Consolidado!C21) -> 1.9246803 | S2: =Cronogramas!C18-Balanco_Consolidado!C5 -> -123395.7 | U2: =IF(Cronogramas!C22=0,0,DRE_Consolidado!C20/Cronogramas!C22) -> 0.55407426 | W2: =DFC_Consolidado!C13 -> -7980.5669 | X2: =Balanco_Consolidado!C9-Balanco_Consolidado!C21 -> 368433.66
A3: 2025 | B3: 2 | C3: 2025-02 | D3: 45689 | E3: =DRE_Consolidado!D4 -> 250904.51 | F3: =DRE_Consolidado!D6 -> 170458.93 | G3: =IF(DRE_Consolidado!C4=0,0,DRE_Consolidado!D4/DRE_Consolidado!C4-1) -> -0.040085339 | I3: =DRE_Consolidado!D9 -> 0.43940798 | J3: =DRE_Consolidado!D18 -> 0.030363089 | K3: =DRE_Consolidado!D25 -> -0.0050762032 | L3: =DRE_Consolidado!D17 -> 5175.6597 | M3: =DRE_Consolidado!D24 -> -865.28417 | N3: =IF(DRE_Consolidado!D6=0,0,Balanco_Consolidado!D6/DRE_Consolidado!D6*30) -> 21.251687 | O3: =IF(DRE_Consolidado!D7=0,0,Balanco_Consolidado!D7/(-DRE_Consolidado!D7)*30) -> 52.659437 | P3: =IF(DRE_Consolidado!D7=0,0,Balanco_Consolidado!D16/(-DRE_Consolidado!D7)*30) -> 43.514923 | Q3: =N3+O3-P3 -> 30.396201 | R3: =IF(Balanco_Consolidado!D21=0,0,Balanco_Consolidado!D9/Balanco_Consolidado!D21) -> 1.9323771 | S3: =Cronogramas!D18-Balanco_Consolidado!D5 -> -134118.14 | U3: =IF(Cronogramas!D22=0,0,DRE_Consolidado!D20/Cronogramas!D22) -> 0.05752972 | W3: =DFC_Consolidado!D13 -> 13279.324 | X3: =Balanco_Consolidado!D9-Balanco_Consolidado!D21 -> 364888
A4: 2025 | B4: 3 | C4: 2025-03 | D4: 45717 | E4: =DRE_Consolidado!E4 -> 277234.2 | F4: =DRE_Consolidado!E6 -> 186625.07 | G4: =IF(DRE_Consolidado!D4=0,0,DRE_Consolidado!E4/DRE_Consolidado!D4-1) -> 0.10493909 | I4: =DRE_Consolidado!E9 -> 0.4460258 | J4: =DRE_Consolidado!E18 -> 0.066190525 | K4: =DRE_Consolidado!E25 -> 0.022704491 | L4: =DRE_Consolidado!E17 -> 12352.811 | M4: =DRE_Consolidado!E24 -> 4237.2272 | N4: =IF(DRE_Consolidado!E6=0,0,Balanco_Consolidado!E6/DRE_Consolidado!E6*30) -> 22.069164 | O4: =IF(DRE_Consolidado!E7=0,0,Balanco_Consolidado!E7/(-DRE_Consolidado!E7)*30) -> 52.907089 | P4: =IF(DRE_Consolidado!E7=0,0,Balanco_Consolidado!E16/(-DRE_Consolidado!E7)*30) -> 43.69562 | Q4: =N4+O4-P4 -> 31.280633 | R4: =IF(Balanco_Consolidado!E21=0,0,Balanco_Consolidado!E9/Balanco_Consolidado!E21) -> 1.8776246 | S4: =Cronogramas!E18-Balanco_Consolidado!E5 -> -133971.48 | U4: =IF(Cronogramas!E22=0,0,DRE_Consolidado!E20/Cronogramas!E22) -> 1.4556598 | W4: =DFC_Consolidado!E13 -> 2652.7199 | X4: =Balanco_Consolidado!E9-Balanco_Consolidado!E21 -> 366225.68
A5: 2025 | B5: 4 | C5: 2025-04 | D5: 45748 | E5: =DRE_Consolidado!F4 -> 280943.75 | F5: =DRE_Consolidado!F6 -> 191404.44 | G5: =IF(DRE_Consolidado!E4=0,0,DRE_Consolidado!F4/DRE_Consolidado!E4-1) -> 0.013380564 | I5: =DRE_Consolidado!F9 -> 0.44692125 | J5: =DRE_Consolidado!F18 -> 0.075322908 | K5: =DRE_Consolidado!F25 -> 0.029289402 | L5: =DRE_Consolidado!F17 -> 14417.139 | M5: =DRE_Consolidado!F24 -> 5606.1216 | N5: =IF(DRE_Consolidado!F6=0,0,Balanco_Consolidado!F6/DRE_Consolidado!F6*30) -> 21.101012 | O5: =IF(DRE_Consolidado!F7=0,0,Balanco_Consolidado!F7/(-DRE_Consolidado!F7)*30) -> 52.611619 | P5: =IF(DRE_Consolidado!F7=0,0,Balanco_Consolidado!F16/(-DRE_Consolidado!F7)*30) -> 43.53906 | Q5: =N5+O5-P5 -> 30.173571 | R5: =IF(Balanco_Consolidado!F21=0,0,Balanco_Consolidado!F9/Balanco_Consolidado!F21) -> 1.8773366 | S5: =Cronogramas!F18-Balanco_Consolidado!F5 -> -143752.16 | U5: =IF(Cronogramas!F22=0,0,DRE_Consolidado!F20/Cronogramas!F22) -> 1.8836072 | W5: =DFC_Consolidado!F13 -> 12651.743 | X5: =Balanco_Consolidado!F9-Balanco_Consolidado!F21 -> 368884.5
A6: 2025 | B6: 5 | C6: 2025-05 | D6: 45778 | E6: =DRE_Consolidado!G4 -> 285858.47 | F6: =DRE_Consolidado!G6 -> 193794.49 | G6: =IF(DRE_Consolidado!F4=0,0,DRE_Consolidado!G4/DRE_Consolidado!F4-1) -> 0.017493609 | I6: =DRE_Consolidado!G9 -> 0.44212031 | J6: =DRE_Consolidado!G18 -> 0.073626625 | K6: =DRE_Consolidado!G25 -> 0.028758225 | L6: =DRE_Consolidado!G17 -> 14268.434 | M6: =DRE_Consolidado!G24 -> 5573.1855 | N6: =IF(DRE_Consolidado!G6=0,0,Balanco_Consolidado!G6/DRE_Consolidado!G6*30) -> 21.754401 | O6: =IF(DRE_Consolidado!G7=0,0,Balanco_Consolidado!G7/(-DRE_Consolidado!G7)*30) -> 52.843658 | P6: =IF(DRE_Consolidado!G7=0,0,Balanco_Consolidado!G16/(-DRE_Consolidado!G7)*30) -> 43.619203 | Q6: =N6+O6-P6 -> 30.978857 | R6: =IF(Balanco_Consolidado!G21=0,0,Balanco_Consolidado!G9/Balanco_Consolidado!G21) -> 1.8705021 | S6: =Cronogramas!G18-Balanco_Consolidado!G5 -> -146791.52 | U6: =IF(Cronogramas!G22=0,0,DRE_Consolidado!G20/Cronogramas!G22) -> 1.8791232 | W6: =DFC_Consolidado!G13 -> 5946.2811 | X6: =Balanco_Consolidado!G9-Balanco_Consolidado!G21 -> 371498.75
A7: 2025 | B7: 6 | C7: 2025-06 | D7: 45809 | E7: =DRE_Consolidado!H4 -> 311626.4 | F7: =DRE_Consolidado!H6 -> 210558.51 | G7: =IF(DRE_Consolidado!G4=0,0,DRE_Consolidado!H4/DRE_Consolidado!G4-1) -> 0.090142265 | I7: =DRE_Consolidado!H9 -> 0.43931046 | J7: =DRE_Consolidado!H18 -> 0.0939395 | K7: =DRE_Consolidado!H25 -> 0.043073272 | L7: =DRE_Consolidado!H17 -> 19779.761 | M7: =DRE_Consolidado!H24 -> 9069.4441 | N7: =IF(DRE_Consolidado!H6=0,0,Balanco_Consolidado!H6/DRE_Consolidado!H6*30) -> 20.713851 | O7: =IF(DRE_Consolidado!H7=0,0,Balanco_Consolidado!H7/(-DRE_Consolidado!H7)*30) -> 53.356175 | P7: =IF(DRE_Consolidado!H7=0,0,Balanco_Consolidado!H16/(-DRE_Consolidado!H7)*30) -> 44.036034 | Q7: =N7+O7-P7 -> 30.033992 | R7: =IF(Balanco_Consolidado!H21=0,0,Balanco_Consolidado!H9/Balanco_Consolidado!H21) -> 1.7634542 | S7: =Cronogramas!H18-Balanco_Consolidado!H5 -> -130779.9 | U7: =IF(Cronogramas!H22=0,0,DRE_Consolidado!H20/Cronogramas!H22) -> 2.9826759 | W7: =DFC_Consolidado!H13 -> 17146.758 | X7: =Balanco_Consolidado!H9-Balanco_Consolidado!H21 -> 347634.12
A8: 2025 | B8: 7 | C8: 2025-07 | D8: 45839 | E8: =DRE_Consolidado!I4 -> 314185.58 | F8: =DRE_Consolidado!I6 -> 213188.47 | G8: =IF(DRE_Consolidado!H4=0,0,DRE_Consolidado!I4/DRE_Consolidado!H4-1) -> 0.0082123337 | I8: =DRE_Consolidado!I9 -> 0.44053193 | J8: =DRE_Consolidado!I18 -> 0.099145604 | K8: =DRE_Consolidado!I25 -> 0.045548553 | L8: =DRE_Consolidado!I17 -> 21136.7 | M8: =DRE_Consolidado!I24 -> 9710.4263 | N8: =IF(DRE_Consolidado!I6=0,0,Balanco_Consolidado!I6/DRE_Consolidado!I6*30) -> 20.832509 | O8: =IF(DRE_Consolidado!I7=0,0,Balanco_Consolidado!I7/(-DRE_Consolidado!I7)*30) -> 52.875119 | P8: =IF(DRE_Consolidado!I7=0,0,Balanco_Consolidado!I16/(-DRE_Consolidado!I7)*30) -> 43.726795 | Q8: =N8+O8-P8 -> 29.980833 | R8: =IF(Balanco_Consolidado!I21=0,0,Balanco_Consolidado!I9/Balanco_Consolidado!I21) -> 1.7112931 | S8: =Cronogramas!I18-Balanco_Consolidado!I5 -> -110752.26 | U8: =IF(Cronogramas!I22=0,0,DRE_Consolidado!I20/Cronogramas!I22) -> 3.2574475 | W8: =DFC_Consolidado!I13 -> 13170.184 | X8: =Balanco_Consolidado!I9-Balanco_Consolidado!I21 -> 324647.67
A9: 2025 | B9: 8 | C9: 2025-08 | D9: 45870 | E9: =DRE_Consolidado!J4 -> 276259.76 | F9: =DRE_Consolidado!J6 -> 187870.5 | G9: =IF(DRE_Consolidado!I4=0,0,DRE_Consolidado!J4/DRE_Consolidado!I4-1) -> -0.12071152 | I9: =DRE_Consolidado!J9 -> 0.44354769 | J9: =DRE_Consolidado!J18 -> 0.065162589 | K9: =DRE_Consolidado!J25 -> 0.018968628 | L9: =DRE_Consolidado!J17 -> 12242.128 | M9: =DRE_Consolidado!J24 -> 3563.6457 | N9: =IF(DRE_Consolidado!J6=0,0,Balanco_Consolidado!J6/DRE_Consolidado!J6*30) -> 21.405846 | O9: =IF(DRE_Consolidado!J7=0,0,Balanco_Consolidado!J7/(-DRE_Consolidado!J7)*30) -> 53.434741 | P9: =IF(DRE_Consolidado!J7=0,0,Balanco_Consolidado!J16/(-DRE_Consolidado!J7)*30) -> 44.133325 | Q9: =N9+O9-P9 -> 30.707263 | R9: =IF(Balanco_Consolidado!J21=0,0,Balanco_Consolidado!J9/Balanco_Consolidado!J21) -> 1.708437 | S9: =Cronogramas!J18-Balanco_Consolidado!J5 -> -88941.039 | U9: =IF(Cronogramas!J22=0,0,DRE_Consolidado!J20/Cronogramas!J22) -> 1.3702739 | W9: =DFC_Consolidado!J13 -> 11006.837 | X9: =Balanco_Consolidado!J9-Balanco_Consolidado!J21 -> 296167.69
A10: 2025 | B10: 9 | C10: 2025-09 | D10: 45901 | E10: =DRE_Consolidado!K4 -> 285962.46 | F10: =DRE_Consolidado!K6 -> 190314.06 | G10: =IF(DRE_Consolidado!J4=0,0,DRE_Consolidado!K4/DRE_Consolidado!J4-1) -> 0.035121655 | I10: =DRE_Consolidado!K9 -> 0.4468813 | J10: =DRE_Consolidado!K18 -> 0.072612913 | K10: =DRE_Consolidado!K25 -> 0.023552606 | L10: =DRE_Consolidado!K17 -> 13819.258 | M10: =DRE_Consolidado!K24 -> 4482.392 | N10: =IF(DRE_Consolidado!K6=0,0,Balanco_Consolidado!K6/DRE_Consolidado!K6*30) -> 22.859468 | O10: =IF(DRE_Consolidado!K7=0,0,Balanco_Consolidado!K7/(-DRE_Consolidado!K7)*30) -> 53.081718 | P10: =IF(DRE_Consolidado!K7=0,0,Balanco_Consolidado!K16/(-DRE_Consolidado!K7)*30) -> 43.496799 | Q10: =N10+O10-P10 -> 32.444387 | R10: =IF(Balanco_Consolidado!K21=0,0,Balanco_Consolidado!K9/Balanco_Consolidado!K21) -> 1.7027912 | S10: =Cronogramas!K18-Balanco_Consolidado!K5 -> -91963.564 | U10: =IF(Cronogramas!K22=0,0,DRE_Consolidado!K20/Cronogramas!K22) -> 1.7286711 | W10: =DFC_Consolidado!K13 -> 5877.236 | X10: =Balanco_Consolidado!K9-Balanco_Consolidado!K21 -> 298593.6
